[2025-07-07T22:16:55.392+0200] {taskinstance.py:1979} INFO - Dependencies all met for dep_context=non-requeueable deps ti=<TaskInstance: daily_prediction.predict_on_daily_data manual__2025-07-07T20:16:50.692379+00:00 [queued]>
[2025-07-07T22:16:55.398+0200] {taskinstance.py:1979} INFO - Dependencies all met for dep_context=requeueable deps ti=<TaskInstance: daily_prediction.predict_on_daily_data manual__2025-07-07T20:16:50.692379+00:00 [queued]>
[2025-07-07T22:16:55.399+0200] {taskinstance.py:2193} INFO - Starting attempt 1 of 2
[2025-07-07T22:16:55.413+0200] {taskinstance.py:2217} INFO - Executing <Task(PythonOperator): predict_on_daily_data> on 2025-07-07 20:16:50.692379+00:00
[2025-07-07T22:16:55.423+0200] {standard_task_runner.py:60} INFO - Started process 87328 to run task
[2025-07-07T22:16:55.433+0200] {standard_task_runner.py:87} INFO - Running: ['airflow', 'tasks', 'run', 'daily_prediction', 'predict_on_daily_data', 'manual__2025-07-07T20:16:50.692379+00:00', '--job-id', '8', '--raw', '--subdir', 'DAGS_FOLDER/dag_daily_prediction.py', '--cfg-path', '/tmp/tmpvn86qnm_']
[2025-07-07T22:16:55.436+0200] {standard_task_runner.py:88} INFO - Job 8: Subtask predict_on_daily_data
[2025-07-07T22:16:55.598+0200] {task_command.py:423} INFO - Running <TaskInstance: daily_prediction.predict_on_daily_data manual__2025-07-07T20:16:50.692379+00:00 [running]> on host Datacraft-AC.localdomain
[2025-07-07T22:16:55.659+0200] {taskinstance.py:2513} INFO - Exporting env vars: AIRFLOW_CTX_DAG_OWNER='airflow' AIRFLOW_CTX_DAG_ID='daily_prediction' AIRFLOW_CTX_TASK_ID='predict_on_daily_data' AIRFLOW_CTX_EXECUTION_DATE='2025-07-07T20:16:50.692379+00:00' AIRFLOW_CTX_TRY_NUMBER='1' AIRFLOW_CTX_DAG_RUN_ID='manual__2025-07-07T20:16:50.692379+00:00'
[2025-07-07T22:16:56.259+0200] {taskinstance.py:2731} ERROR - Task failed with exception
Traceback (most recent call last):
  File "/home/arthurcornelio88/jedha/automatic_fraud_detection_b3/dataops_pipeline/.venv/lib/python3.11/site-packages/airflow/models/taskinstance.py", line 444, in _execute_task
    result = _execute_callable(context=context, **execute_callable_kwargs)
             ^^^^^^^^^^^^^^^^^^^^^^^^^^^^^^^^^^^^^^^^^^^^^^^^^^^^^^^^^^^^^
  File "/home/arthurcornelio88/jedha/automatic_fraud_detection_b3/dataops_pipeline/.venv/lib/python3.11/site-packages/airflow/models/taskinstance.py", line 414, in _execute_callable
    return execute_callable(context=context, **execute_callable_kwargs)
           ^^^^^^^^^^^^^^^^^^^^^^^^^^^^^^^^^^^^^^^^^^^^^^^^^^^^^^^^^^^^
  File "/home/arthurcornelio88/jedha/automatic_fraud_detection_b3/dataops_pipeline/.venv/lib/python3.11/site-packages/airflow/operators/python.py", line 200, in execute
    return_value = self.execute_callable()
                   ^^^^^^^^^^^^^^^^^^^^^^^
  File "/home/arthurcornelio88/jedha/automatic_fraud_detection_b3/dataops_pipeline/.venv/lib/python3.11/site-packages/airflow/operators/python.py", line 217, in execute_callable
    return self.python_callable(*self.op_args, **self.op_kwargs)
           ^^^^^^^^^^^^^^^^^^^^^^^^^^^^^^^^^^^^^^^^^^^^^^^^^^^^^
  File "/home/arthurcornelio88/jedha/automatic_fraud_detection_b3/dataops_pipeline/dags/dag_daily_prediction.py", line 25, in run_daily_prediction
    df = bq.query(f"SELECT * FROM `{raw_table}`").to_dataframe()
         ^^^^^^^^^^^^^^^^^^^^^^^^^^^^^^^^^^^^^^^^^^^^^^^^^^^^^^^
  File "/home/arthurcornelio88/jedha/automatic_fraud_detection_b3/dataops_pipeline/.venv/lib/python3.11/site-packages/google/cloud/bigquery/job/query.py", line 1937, in to_dataframe
    query_result = wait_for_query(self, progress_bar_type, max_results=max_results)
                   ^^^^^^^^^^^^^^^^^^^^^^^^^^^^^^^^^^^^^^^^^^^^^^^^^^^^^^^^^^^^^^^^
  File "/home/arthurcornelio88/jedha/automatic_fraud_detection_b3/dataops_pipeline/.venv/lib/python3.11/site-packages/google/cloud/bigquery/_tqdm_helpers.py", line 107, in wait_for_query
    return query_job.result(max_results=max_results)
           ^^^^^^^^^^^^^^^^^^^^^^^^^^^^^^^^^^^^^^^^^
  File "/home/arthurcornelio88/jedha/automatic_fraud_detection_b3/dataops_pipeline/.venv/lib/python3.11/site-packages/google/cloud/bigquery/job/query.py", line 1626, in result
    while not is_job_done():
              ^^^^^^^^^^^^^
  File "/home/arthurcornelio88/jedha/automatic_fraud_detection_b3/dataops_pipeline/.venv/lib/python3.11/site-packages/google/api_core/retry/retry_unary.py", line 294, in retry_wrapped_func
    return retry_target(
           ^^^^^^^^^^^^^
  File "/home/arthurcornelio88/jedha/automatic_fraud_detection_b3/dataops_pipeline/.venv/lib/python3.11/site-packages/google/api_core/retry/retry_unary.py", line 156, in retry_target
    next_sleep = _retry_error_helper(
                 ^^^^^^^^^^^^^^^^^^^^
  File "/home/arthurcornelio88/jedha/automatic_fraud_detection_b3/dataops_pipeline/.venv/lib/python3.11/site-packages/google/api_core/retry/retry_base.py", line 214, in _retry_error_helper
    raise final_exc from source_exc
  File "/home/arthurcornelio88/jedha/automatic_fraud_detection_b3/dataops_pipeline/.venv/lib/python3.11/site-packages/google/api_core/retry/retry_unary.py", line 147, in retry_target
    result = target()
             ^^^^^^^^
  File "/home/arthurcornelio88/jedha/automatic_fraud_detection_b3/dataops_pipeline/.venv/lib/python3.11/site-packages/google/cloud/bigquery/job/query.py", line 1577, in is_job_done
    raise job_failed_exception
google.api_core.exceptions.NotFound: 404 Not found: Table jedha2024:raw_api_data.daily_20250707 was not found in location EU; reason: notFound, message: Not found: Table jedha2024:raw_api_data.daily_20250707 was not found in location EU

Location: EU
Job ID: 39f0775d-1e42-43f6-8dae-34a7249940fe

[2025-07-07T22:16:56.263+0200] {taskinstance.py:1149} INFO - Marking task as UP_FOR_RETRY. dag_id=daily_prediction, task_id=predict_on_daily_data, execution_date=20250707T201650, start_date=20250707T201655, end_date=20250707T201656
[2025-07-07T22:16:56.272+0200] {standard_task_runner.py:107} ERROR - Failed to execute job 8 for task predict_on_daily_data (404 Not found: Table jedha2024:raw_api_data.daily_20250707 was not found in location EU; reason: notFound, message: Not found: Table jedha2024:raw_api_data.daily_20250707 was not found in location EU

Location: EU
Job ID: 39f0775d-1e42-43f6-8dae-34a7249940fe
; 87328)
[2025-07-07T22:16:56.290+0200] {local_task_job_runner.py:234} INFO - Task exited with return code 1
[2025-07-07T22:16:56.300+0200] {taskinstance.py:3312} INFO - 0 downstream tasks scheduled from follow-on schedule check
