[2025-07-08T20:34:01.374+0200] {taskinstance.py:1979} INFO - Dependencies all met for dep_context=non-requeueable deps ti=<TaskInstance: daily_fetch_transactions.fetch_transactions_to_bigquery scheduled__2025-07-07T00:00:00+00:00 [queued]>
[2025-07-08T20:34:01.382+0200] {taskinstance.py:1979} INFO - Dependencies all met for dep_context=requeueable deps ti=<TaskInstance: daily_fetch_transactions.fetch_transactions_to_bigquery scheduled__2025-07-07T00:00:00+00:00 [queued]>
[2025-07-08T20:34:01.383+0200] {taskinstance.py:2193} INFO - Starting attempt 2 of 2
[2025-07-08T20:34:01.399+0200] {taskinstance.py:2217} INFO - Executing <Task(PythonOperator): fetch_transactions_to_bigquery> on 2025-07-07 00:00:00+00:00
[2025-07-08T20:34:01.411+0200] {standard_task_runner.py:60} INFO - Started process 20029 to run task
[2025-07-08T20:34:01.417+0200] {standard_task_runner.py:87} INFO - Running: ['airflow', 'tasks', 'run', 'daily_fetch_transactions', 'fetch_transactions_to_bigquery', 'scheduled__2025-07-07T00:00:00+00:00', '--job-id', '6', '--raw', '--subdir', 'DAGS_FOLDER/dag_daily_fetch_transactions.py', '--cfg-path', '/tmp/tmpkrok0696']
[2025-07-08T20:34:01.421+0200] {standard_task_runner.py:88} INFO - Job 6: Subtask fetch_transactions_to_bigquery
[2025-07-08T20:34:01.470+0200] {task_command.py:423} INFO - Running <TaskInstance: daily_fetch_transactions.fetch_transactions_to_bigquery scheduled__2025-07-07T00:00:00+00:00 [running]> on host Datacraft-AC.localdomain
[2025-07-08T20:34:01.516+0200] {taskinstance.py:2513} INFO - Exporting env vars: AIRFLOW_CTX_DAG_OWNER='airflow' AIRFLOW_CTX_DAG_ID='daily_fetch_transactions' AIRFLOW_CTX_TASK_ID='fetch_transactions_to_bigquery' AIRFLOW_CTX_EXECUTION_DATE='2025-07-07T00:00:00+00:00' AIRFLOW_CTX_TRY_NUMBER='2' AIRFLOW_CTX_DAG_RUN_ID='scheduled__2025-07-07T00:00:00+00:00'
[2025-07-08T20:34:01.521+0200] {taskinstance.py:2731} ERROR - Task failed with exception
Traceback (most recent call last):
  File "/home/arthurcornelio88/jedha/automatic_fraud_detection_b3/dataops_pipeline/.venv/lib/python3.11/site-packages/urllib3/connection.py", line 198, in _new_conn
    sock = connection.create_connection(
           ^^^^^^^^^^^^^^^^^^^^^^^^^^^^^
  File "/home/arthurcornelio88/jedha/automatic_fraud_detection_b3/dataops_pipeline/.venv/lib/python3.11/site-packages/urllib3/util/connection.py", line 85, in create_connection
    raise err
  File "/home/arthurcornelio88/jedha/automatic_fraud_detection_b3/dataops_pipeline/.venv/lib/python3.11/site-packages/urllib3/util/connection.py", line 73, in create_connection
    sock.connect(sa)
ConnectionRefusedError: [Errno 111] Connection refused

The above exception was the direct cause of the following exception:

Traceback (most recent call last):
  File "/home/arthurcornelio88/jedha/automatic_fraud_detection_b3/dataops_pipeline/.venv/lib/python3.11/site-packages/urllib3/connectionpool.py", line 787, in urlopen
    response = self._make_request(
               ^^^^^^^^^^^^^^^^^^^
  File "/home/arthurcornelio88/jedha/automatic_fraud_detection_b3/dataops_pipeline/.venv/lib/python3.11/site-packages/urllib3/connectionpool.py", line 493, in _make_request
    conn.request(
  File "/home/arthurcornelio88/jedha/automatic_fraud_detection_b3/dataops_pipeline/.venv/lib/python3.11/site-packages/urllib3/connection.py", line 494, in request
    self.endheaders()
  File "/home/arthurcornelio88/.local/share/uv/python/cpython-3.11.13-linux-x86_64-gnu/lib/python3.11/http/client.py", line 1298, in endheaders
    self._send_output(message_body, encode_chunked=encode_chunked)
  File "/home/arthurcornelio88/.local/share/uv/python/cpython-3.11.13-linux-x86_64-gnu/lib/python3.11/http/client.py", line 1058, in _send_output
    self.send(msg)
  File "/home/arthurcornelio88/.local/share/uv/python/cpython-3.11.13-linux-x86_64-gnu/lib/python3.11/http/client.py", line 996, in send
    self.connect()
  File "/home/arthurcornelio88/jedha/automatic_fraud_detection_b3/dataops_pipeline/.venv/lib/python3.11/site-packages/urllib3/connection.py", line 325, in connect
    self.sock = self._new_conn()
                ^^^^^^^^^^^^^^^^
  File "/home/arthurcornelio88/jedha/automatic_fraud_detection_b3/dataops_pipeline/.venv/lib/python3.11/site-packages/urllib3/connection.py", line 213, in _new_conn
    raise NewConnectionError(
urllib3.exceptions.NewConnectionError: <urllib3.connection.HTTPConnection object at 0x78414e5308d0>: Failed to establish a new connection: [Errno 111] Connection refused

The above exception was the direct cause of the following exception:

Traceback (most recent call last):
  File "/home/arthurcornelio88/jedha/automatic_fraud_detection_b3/dataops_pipeline/.venv/lib/python3.11/site-packages/requests/adapters.py", line 667, in send
    resp = conn.urlopen(
           ^^^^^^^^^^^^^
  File "/home/arthurcornelio88/jedha/automatic_fraud_detection_b3/dataops_pipeline/.venv/lib/python3.11/site-packages/urllib3/connectionpool.py", line 841, in urlopen
    retries = retries.increment(
              ^^^^^^^^^^^^^^^^^^
  File "/home/arthurcornelio88/jedha/automatic_fraud_detection_b3/dataops_pipeline/.venv/lib/python3.11/site-packages/urllib3/util/retry.py", line 519, in increment
    raise MaxRetryError(_pool, url, reason) from reason  # type: ignore[arg-type]
    ^^^^^^^^^^^^^^^^^^^^^^^^^^^^^^^^^^^^^^^^^^^^^^^^^^^
urllib3.exceptions.MaxRetryError: HTTPConnectionPool(host='localhost', port=8001): Max retries exceeded with url: /transactions?n=500 (Caused by NewConnectionError('<urllib3.connection.HTTPConnection object at 0x78414e5308d0>: Failed to establish a new connection: [Errno 111] Connection refused'))

During handling of the above exception, another exception occurred:

Traceback (most recent call last):
  File "/home/arthurcornelio88/jedha/automatic_fraud_detection_b3/dataops_pipeline/.venv/lib/python3.11/site-packages/airflow/models/taskinstance.py", line 444, in _execute_task
    result = _execute_callable(context=context, **execute_callable_kwargs)
             ^^^^^^^^^^^^^^^^^^^^^^^^^^^^^^^^^^^^^^^^^^^^^^^^^^^^^^^^^^^^^
  File "/home/arthurcornelio88/jedha/automatic_fraud_detection_b3/dataops_pipeline/.venv/lib/python3.11/site-packages/airflow/models/taskinstance.py", line 414, in _execute_callable
    return execute_callable(context=context, **execute_callable_kwargs)
           ^^^^^^^^^^^^^^^^^^^^^^^^^^^^^^^^^^^^^^^^^^^^^^^^^^^^^^^^^^^^
  File "/home/arthurcornelio88/jedha/automatic_fraud_detection_b3/dataops_pipeline/.venv/lib/python3.11/site-packages/airflow/operators/python.py", line 200, in execute
    return_value = self.execute_callable()
                   ^^^^^^^^^^^^^^^^^^^^^^^
  File "/home/arthurcornelio88/jedha/automatic_fraud_detection_b3/dataops_pipeline/.venv/lib/python3.11/site-packages/airflow/operators/python.py", line 217, in execute_callable
    return self.python_callable(*self.op_args, **self.op_kwargs)
           ^^^^^^^^^^^^^^^^^^^^^^^^^^^^^^^^^^^^^^^^^^^^^^^^^^^^^
  File "/home/arthurcornelio88/jedha/automatic_fraud_detection_b3/dataops_pipeline/dags/dag_daily_fetch_transactions.py", line 27, in fetch_transactions_to_bq
    response = requests.get(f"{url}?n={n}")
               ^^^^^^^^^^^^^^^^^^^^^^^^^^^^
  File "/home/arthurcornelio88/jedha/automatic_fraud_detection_b3/dataops_pipeline/.venv/lib/python3.11/site-packages/requests/api.py", line 73, in get
    return request("get", url, params=params, **kwargs)
           ^^^^^^^^^^^^^^^^^^^^^^^^^^^^^^^^^^^^^^^^^^^^
  File "/home/arthurcornelio88/jedha/automatic_fraud_detection_b3/dataops_pipeline/.venv/lib/python3.11/site-packages/requests/api.py", line 59, in request
    return session.request(method=method, url=url, **kwargs)
           ^^^^^^^^^^^^^^^^^^^^^^^^^^^^^^^^^^^^^^^^^^^^^^^^^
  File "/home/arthurcornelio88/jedha/automatic_fraud_detection_b3/dataops_pipeline/.venv/lib/python3.11/site-packages/requests/sessions.py", line 589, in request
    resp = self.send(prep, **send_kwargs)
           ^^^^^^^^^^^^^^^^^^^^^^^^^^^^^^
  File "/home/arthurcornelio88/jedha/automatic_fraud_detection_b3/dataops_pipeline/.venv/lib/python3.11/site-packages/requests/sessions.py", line 703, in send
    r = adapter.send(request, **kwargs)
        ^^^^^^^^^^^^^^^^^^^^^^^^^^^^^^^
  File "/home/arthurcornelio88/jedha/automatic_fraud_detection_b3/dataops_pipeline/.venv/lib/python3.11/site-packages/requests/adapters.py", line 700, in send
    raise ConnectionError(e, request=request)
requests.exceptions.ConnectionError: HTTPConnectionPool(host='localhost', port=8001): Max retries exceeded with url: /transactions?n=500 (Caused by NewConnectionError('<urllib3.connection.HTTPConnection object at 0x78414e5308d0>: Failed to establish a new connection: [Errno 111] Connection refused'))
[2025-07-08T20:34:01.528+0200] {taskinstance.py:1149} INFO - Marking task as FAILED. dag_id=daily_fetch_transactions, task_id=fetch_transactions_to_bigquery, execution_date=20250707T000000, start_date=20250708T183401, end_date=20250708T183401
[2025-07-08T20:34:01.538+0200] {standard_task_runner.py:107} ERROR - Failed to execute job 6 for task fetch_transactions_to_bigquery (HTTPConnectionPool(host='localhost', port=8001): Max retries exceeded with url: /transactions?n=500 (Caused by NewConnectionError('<urllib3.connection.HTTPConnection object at 0x78414e5308d0>: Failed to establish a new connection: [Errno 111] Connection refused')); 20029)
[2025-07-08T20:34:01.591+0200] {local_task_job_runner.py:234} INFO - Task exited with return code 1
[2025-07-08T20:34:01.606+0200] {taskinstance.py:3312} INFO - 0 downstream tasks scheduled from follow-on schedule check
