[2025-07-07T22:50:33.272+0200] {taskinstance.py:1979} INFO - Dependencies all met for dep_context=non-requeueable deps ti=<TaskInstance: daily_prediction.predict_on_daily_data manual__2025-07-07T20:48:24.362924+00:00 [queued]>
[2025-07-07T22:50:33.277+0200] {taskinstance.py:1979} INFO - Dependencies all met for dep_context=requeueable deps ti=<TaskInstance: daily_prediction.predict_on_daily_data manual__2025-07-07T20:48:24.362924+00:00 [queued]>
[2025-07-07T22:50:33.277+0200] {taskinstance.py:2193} INFO - Starting attempt 2 of 2
[2025-07-07T22:50:33.288+0200] {taskinstance.py:2217} INFO - Executing <Task(PythonOperator): predict_on_daily_data> on 2025-07-07 20:48:24.362924+00:00
[2025-07-07T22:50:33.294+0200] {standard_task_runner.py:60} INFO - Started process 5947 to run task
[2025-07-07T22:50:33.298+0200] {standard_task_runner.py:87} INFO - Running: ['airflow', 'tasks', 'run', 'daily_prediction', 'predict_on_daily_data', 'manual__2025-07-07T20:48:24.362924+00:00', '--job-id', '21', '--raw', '--subdir', 'DAGS_FOLDER/dag_daily_prediction.py', '--cfg-path', '/tmp/tmp71nr141j']
[2025-07-07T22:50:33.300+0200] {standard_task_runner.py:88} INFO - Job 21: Subtask predict_on_daily_data
[2025-07-07T22:50:33.332+0200] {task_command.py:423} INFO - Running <TaskInstance: daily_prediction.predict_on_daily_data manual__2025-07-07T20:48:24.362924+00:00 [running]> on host Datacraft-AC.localdomain
[2025-07-07T22:50:33.370+0200] {taskinstance.py:2513} INFO - Exporting env vars: AIRFLOW_CTX_DAG_OWNER='airflow' AIRFLOW_CTX_DAG_ID='daily_prediction' AIRFLOW_CTX_TASK_ID='predict_on_daily_data' AIRFLOW_CTX_EXECUTION_DATE='2025-07-07T20:48:24.362924+00:00' AIRFLOW_CTX_TRY_NUMBER='2' AIRFLOW_CTX_DAG_RUN_ID='manual__2025-07-07T20:48:24.362924+00:00'
[2025-07-07T22:50:34.637+0200] {taskinstance.py:2731} ERROR - Task failed with exception
Traceback (most recent call last):
  File "/home/arthurcornelio88/jedha/automatic_fraud_detection_b3/dataops_pipeline/.venv/lib/python3.11/site-packages/airflow/models/taskinstance.py", line 444, in _execute_task
    result = _execute_callable(context=context, **execute_callable_kwargs)
             ^^^^^^^^^^^^^^^^^^^^^^^^^^^^^^^^^^^^^^^^^^^^^^^^^^^^^^^^^^^^^
  File "/home/arthurcornelio88/jedha/automatic_fraud_detection_b3/dataops_pipeline/.venv/lib/python3.11/site-packages/airflow/models/taskinstance.py", line 414, in _execute_callable
    return execute_callable(context=context, **execute_callable_kwargs)
           ^^^^^^^^^^^^^^^^^^^^^^^^^^^^^^^^^^^^^^^^^^^^^^^^^^^^^^^^^^^^
  File "/home/arthurcornelio88/jedha/automatic_fraud_detection_b3/dataops_pipeline/.venv/lib/python3.11/site-packages/airflow/operators/python.py", line 200, in execute
    return_value = self.execute_callable()
                   ^^^^^^^^^^^^^^^^^^^^^^^
  File "/home/arthurcornelio88/jedha/automatic_fraud_detection_b3/dataops_pipeline/.venv/lib/python3.11/site-packages/airflow/operators/python.py", line 217, in execute_callable
    return self.python_callable(*self.op_args, **self.op_kwargs)
           ^^^^^^^^^^^^^^^^^^^^^^^^^^^^^^^^^^^^^^^^^^^^^^^^^^^^^
  File "/home/arthurcornelio88/jedha/automatic_fraud_detection_b3/dataops_pipeline/dags/dag_daily_prediction.py", line 42, in run_daily_prediction
    raise Exception(f"❌ Preprocessing failed: {res.status_code} - {res.text}")
Exception: ❌ Preprocessing failed: 500 - Internal Server Error
[2025-07-07T22:50:34.640+0200] {taskinstance.py:1149} INFO - Marking task as FAILED. dag_id=daily_prediction, task_id=predict_on_daily_data, execution_date=20250707T204824, start_date=20250707T205033, end_date=20250707T205034
[2025-07-07T22:50:34.652+0200] {standard_task_runner.py:107} ERROR - Failed to execute job 21 for task predict_on_daily_data (❌ Preprocessing failed: 500 - Internal Server Error; 5947)
[2025-07-07T22:50:34.678+0200] {local_task_job_runner.py:234} INFO - Task exited with return code 1
[2025-07-07T22:50:34.688+0200] {taskinstance.py:3312} INFO - 0 downstream tasks scheduled from follow-on schedule check
