[2025-07-07T22:19:01.129+0200] {taskinstance.py:1979} INFO - Dependencies all met for dep_context=non-requeueable deps ti=<TaskInstance: daily_prediction.predict_on_daily_data scheduled__2025-07-06T00:00:00+00:00 [queued]>
[2025-07-07T22:19:01.132+0200] {taskinstance.py:1979} INFO - Dependencies all met for dep_context=requeueable deps ti=<TaskInstance: daily_prediction.predict_on_daily_data scheduled__2025-07-06T00:00:00+00:00 [queued]>
[2025-07-07T22:19:01.133+0200] {taskinstance.py:2193} INFO - Starting attempt 2 of 2
[2025-07-07T22:19:01.144+0200] {taskinstance.py:2217} INFO - Executing <Task(PythonOperator): predict_on_daily_data> on 2025-07-06 00:00:00+00:00
[2025-07-07T22:19:01.149+0200] {standard_task_runner.py:60} INFO - Started process 89628 to run task
[2025-07-07T22:19:01.153+0200] {standard_task_runner.py:87} INFO - Running: ['airflow', 'tasks', 'run', 'daily_prediction', 'predict_on_daily_data', 'scheduled__2025-07-06T00:00:00+00:00', '--job-id', '10', '--raw', '--subdir', 'DAGS_FOLDER/dag_daily_prediction.py', '--cfg-path', '/tmp/tmp4tcn7939']
[2025-07-07T22:19:01.158+0200] {standard_task_runner.py:88} INFO - Job 10: Subtask predict_on_daily_data
[2025-07-07T22:19:01.196+0200] {task_command.py:423} INFO - Running <TaskInstance: daily_prediction.predict_on_daily_data scheduled__2025-07-06T00:00:00+00:00 [running]> on host Datacraft-AC.localdomain
[2025-07-07T22:19:01.236+0200] {taskinstance.py:2513} INFO - Exporting env vars: AIRFLOW_CTX_DAG_OWNER='airflow' AIRFLOW_CTX_DAG_ID='daily_prediction' AIRFLOW_CTX_TASK_ID='predict_on_daily_data' AIRFLOW_CTX_EXECUTION_DATE='2025-07-06T00:00:00+00:00' AIRFLOW_CTX_TRY_NUMBER='2' AIRFLOW_CTX_DAG_RUN_ID='scheduled__2025-07-06T00:00:00+00:00'
[2025-07-07T22:19:01.748+0200] {taskinstance.py:2731} ERROR - Task failed with exception
Traceback (most recent call last):
  File "/home/arthurcornelio88/jedha/automatic_fraud_detection_b3/dataops_pipeline/.venv/lib/python3.11/site-packages/airflow/models/taskinstance.py", line 444, in _execute_task
    result = _execute_callable(context=context, **execute_callable_kwargs)
             ^^^^^^^^^^^^^^^^^^^^^^^^^^^^^^^^^^^^^^^^^^^^^^^^^^^^^^^^^^^^^
  File "/home/arthurcornelio88/jedha/automatic_fraud_detection_b3/dataops_pipeline/.venv/lib/python3.11/site-packages/airflow/models/taskinstance.py", line 414, in _execute_callable
    return execute_callable(context=context, **execute_callable_kwargs)
           ^^^^^^^^^^^^^^^^^^^^^^^^^^^^^^^^^^^^^^^^^^^^^^^^^^^^^^^^^^^^
  File "/home/arthurcornelio88/jedha/automatic_fraud_detection_b3/dataops_pipeline/.venv/lib/python3.11/site-packages/airflow/operators/python.py", line 200, in execute
    return_value = self.execute_callable()
                   ^^^^^^^^^^^^^^^^^^^^^^^
  File "/home/arthurcornelio88/jedha/automatic_fraud_detection_b3/dataops_pipeline/.venv/lib/python3.11/site-packages/airflow/operators/python.py", line 217, in execute_callable
    return self.python_callable(*self.op_args, **self.op_kwargs)
           ^^^^^^^^^^^^^^^^^^^^^^^^^^^^^^^^^^^^^^^^^^^^^^^^^^^^^
  File "/home/arthurcornelio88/jedha/automatic_fraud_detection_b3/dataops_pipeline/dags/dag_daily_prediction.py", line 25, in run_daily_prediction
    df = bq.query(f"SELECT * FROM `{raw_table}`").to_dataframe()
         ^^^^^^^^^^^^^^^^^^^^^^^^^^^^^^^^^^^^^^^^^^^^^^^^^^^^^^^
  File "/home/arthurcornelio88/jedha/automatic_fraud_detection_b3/dataops_pipeline/.venv/lib/python3.11/site-packages/google/cloud/bigquery/job/query.py", line 1937, in to_dataframe
    query_result = wait_for_query(self, progress_bar_type, max_results=max_results)
                   ^^^^^^^^^^^^^^^^^^^^^^^^^^^^^^^^^^^^^^^^^^^^^^^^^^^^^^^^^^^^^^^^
  File "/home/arthurcornelio88/jedha/automatic_fraud_detection_b3/dataops_pipeline/.venv/lib/python3.11/site-packages/google/cloud/bigquery/_tqdm_helpers.py", line 107, in wait_for_query
    return query_job.result(max_results=max_results)
           ^^^^^^^^^^^^^^^^^^^^^^^^^^^^^^^^^^^^^^^^^
  File "/home/arthurcornelio88/jedha/automatic_fraud_detection_b3/dataops_pipeline/.venv/lib/python3.11/site-packages/google/cloud/bigquery/job/query.py", line 1626, in result
    while not is_job_done():
              ^^^^^^^^^^^^^
  File "/home/arthurcornelio88/jedha/automatic_fraud_detection_b3/dataops_pipeline/.venv/lib/python3.11/site-packages/google/api_core/retry/retry_unary.py", line 294, in retry_wrapped_func
    return retry_target(
           ^^^^^^^^^^^^^
  File "/home/arthurcornelio88/jedha/automatic_fraud_detection_b3/dataops_pipeline/.venv/lib/python3.11/site-packages/google/api_core/retry/retry_unary.py", line 156, in retry_target
    next_sleep = _retry_error_helper(
                 ^^^^^^^^^^^^^^^^^^^^
  File "/home/arthurcornelio88/jedha/automatic_fraud_detection_b3/dataops_pipeline/.venv/lib/python3.11/site-packages/google/api_core/retry/retry_base.py", line 214, in _retry_error_helper
    raise final_exc from source_exc
  File "/home/arthurcornelio88/jedha/automatic_fraud_detection_b3/dataops_pipeline/.venv/lib/python3.11/site-packages/google/api_core/retry/retry_unary.py", line 147, in retry_target
    result = target()
             ^^^^^^^^
  File "/home/arthurcornelio88/jedha/automatic_fraud_detection_b3/dataops_pipeline/.venv/lib/python3.11/site-packages/google/cloud/bigquery/job/query.py", line 1577, in is_job_done
    raise job_failed_exception
google.api_core.exceptions.NotFound: 404 Not found: Table jedha2024:raw_api_data.daily_20250707 was not found in location EU; reason: notFound, message: Not found: Table jedha2024:raw_api_data.daily_20250707 was not found in location EU

Location: EU
Job ID: a263782a-79b8-4816-add5-32f899c724bf

[2025-07-07T22:19:01.754+0200] {taskinstance.py:1149} INFO - Marking task as FAILED. dag_id=daily_prediction, task_id=predict_on_daily_data, execution_date=20250706T000000, start_date=20250707T201901, end_date=20250707T201901
[2025-07-07T22:19:01.770+0200] {standard_task_runner.py:107} ERROR - Failed to execute job 10 for task predict_on_daily_data (404 Not found: Table jedha2024:raw_api_data.daily_20250707 was not found in location EU; reason: notFound, message: Not found: Table jedha2024:raw_api_data.daily_20250707 was not found in location EU

Location: EU
Job ID: a263782a-79b8-4816-add5-32f899c724bf
; 89628)
[2025-07-07T22:19:01.809+0200] {local_task_job_runner.py:234} INFO - Task exited with return code 1
[2025-07-07T22:19:01.816+0200] {taskinstance.py:3312} INFO - 0 downstream tasks scheduled from follow-on schedule check
