[2025-07-08T20:38:03.868+0200] {taskinstance.py:1979} INFO - Dependencies all met for dep_context=non-requeueable deps ti=<TaskInstance: daily_fetch_transactions.fetch_transactions_to_bigquery manual__2025-07-08T18:38:00.044941+00:00 [queued]>
[2025-07-08T20:38:03.873+0200] {taskinstance.py:1979} INFO - Dependencies all met for dep_context=requeueable deps ti=<TaskInstance: daily_fetch_transactions.fetch_transactions_to_bigquery manual__2025-07-08T18:38:00.044941+00:00 [queued]>
[2025-07-08T20:38:03.873+0200] {taskinstance.py:2193} INFO - Starting attempt 1 of 2
[2025-07-08T20:38:03.884+0200] {taskinstance.py:2217} INFO - Executing <Task(PythonOperator): fetch_transactions_to_bigquery> on 2025-07-08 18:38:00.044941+00:00
[2025-07-08T20:38:03.898+0200] {standard_task_runner.py:60} INFO - Started process 24075 to run task
[2025-07-08T20:38:03.902+0200] {standard_task_runner.py:87} INFO - Running: ['airflow', 'tasks', 'run', 'daily_fetch_transactions', 'fetch_transactions_to_bigquery', 'manual__2025-07-08T18:38:00.044941+00:00', '--job-id', '12', '--raw', '--subdir', 'DAGS_FOLDER/dag_daily_fetch_transactions.py', '--cfg-path', '/tmp/tmp4yyt4kxj']
[2025-07-08T20:38:03.904+0200] {standard_task_runner.py:88} INFO - Job 12: Subtask fetch_transactions_to_bigquery
[2025-07-08T20:38:03.946+0200] {task_command.py:423} INFO - Running <TaskInstance: daily_fetch_transactions.fetch_transactions_to_bigquery manual__2025-07-08T18:38:00.044941+00:00 [running]> on host Datacraft-AC.localdomain
[2025-07-08T20:38:03.990+0200] {taskinstance.py:2513} INFO - Exporting env vars: AIRFLOW_CTX_DAG_OWNER='airflow' AIRFLOW_CTX_DAG_ID='daily_fetch_transactions' AIRFLOW_CTX_TASK_ID='fetch_transactions_to_bigquery' AIRFLOW_CTX_EXECUTION_DATE='2025-07-08T18:38:00.044941+00:00' AIRFLOW_CTX_TRY_NUMBER='1' AIRFLOW_CTX_DAG_RUN_ID='manual__2025-07-08T18:38:00.044941+00:00'
[2025-07-08T20:38:16.648+0200] {logging_mixin.py:188} INFO - Please visit this URL to authorize this application: https://accounts.google.com/o/oauth2/auth?response_type=code&client_id=262006177488-3425ks60hkk80fssi9vpohv88g6q1iqd.apps.googleusercontent.com&redirect_uri=http%3A%2F%2Flocalhost%3A8081%2F&scope=https%3A%2F%2Fwww.googleapis.com%2Fauth%2Fbigquery&state=lWd0Ph6ZFJc4sQD0Gw8aZHEVsMjBBe&prompt=consent&access_type=offline
[2025-07-08T20:38:23.973+0200] {flow.py:476} INFO - "GET /?state=lWd0Ph6ZFJc4sQD0Gw8aZHEVsMjBBe&code=4/0AVMBsJicn1_kUnTZIjzdmNtM_-XDnBwtLvNBqWlKW7CpvgrgZ3oUMrcJBkwLFoCMAQoReQ&scope=https://www.googleapis.com/auth/bigquery HTTP/1.1" 200 65
[2025-07-08T20:38:24.287+0200] {taskinstance.py:2731} ERROR - Task failed with exception
Traceback (most recent call last):
  File "/home/arthurcornelio88/jedha/automatic_fraud_detection_b3/dataops_pipeline/.venv/lib/python3.11/site-packages/airflow/models/taskinstance.py", line 444, in _execute_task
    result = _execute_callable(context=context, **execute_callable_kwargs)
             ^^^^^^^^^^^^^^^^^^^^^^^^^^^^^^^^^^^^^^^^^^^^^^^^^^^^^^^^^^^^^
  File "/home/arthurcornelio88/jedha/automatic_fraud_detection_b3/dataops_pipeline/.venv/lib/python3.11/site-packages/airflow/models/taskinstance.py", line 414, in _execute_callable
    return execute_callable(context=context, **execute_callable_kwargs)
           ^^^^^^^^^^^^^^^^^^^^^^^^^^^^^^^^^^^^^^^^^^^^^^^^^^^^^^^^^^^^
  File "/home/arthurcornelio88/jedha/automatic_fraud_detection_b3/dataops_pipeline/.venv/lib/python3.11/site-packages/airflow/operators/python.py", line 200, in execute
    return_value = self.execute_callable()
                   ^^^^^^^^^^^^^^^^^^^^^^^
  File "/home/arthurcornelio88/jedha/automatic_fraud_detection_b3/dataops_pipeline/.venv/lib/python3.11/site-packages/airflow/operators/python.py", line 217, in execute_callable
    return self.python_callable(*self.op_args, **self.op_kwargs)
           ^^^^^^^^^^^^^^^^^^^^^^^^^^^^^^^^^^^^^^^^^^^^^^^^^^^^^
  File "/home/arthurcornelio88/jedha/automatic_fraud_detection_b3/dataops_pipeline/dags/dag_daily_fetch_transactions.py", line 35, in fetch_transactions_to_bq
    df.to_gbq(destination_table=table_id, project_id=BQ_PROJECT, if_exists="replace", location=BQ_LOCATION)
  File "/home/arthurcornelio88/jedha/automatic_fraud_detection_b3/dataops_pipeline/.venv/lib/python3.11/site-packages/pandas/core/frame.py", line 2158, in to_gbq
    gbq.to_gbq(
  File "/home/arthurcornelio88/jedha/automatic_fraud_detection_b3/dataops_pipeline/.venv/lib/python3.11/site-packages/pandas/io/gbq.py", line 223, in to_gbq
    pandas_gbq.to_gbq(
  File "/home/arthurcornelio88/jedha/automatic_fraud_detection_b3/dataops_pipeline/.venv/lib/python3.11/site-packages/pandas_gbq/gbq.py", line 604, in to_gbq
    table = bqclient.get_table(destination_table_ref)
            ^^^^^^^^^^^^^^^^^^^^^^^^^^^^^^^^^^^^^^^^^
  File "/home/arthurcornelio88/jedha/automatic_fraud_detection_b3/dataops_pipeline/.venv/lib/python3.11/site-packages/google/cloud/bigquery/client.py", line 1158, in get_table
    api_response = self._call_api(
                   ^^^^^^^^^^^^^^^
  File "/home/arthurcornelio88/jedha/automatic_fraud_detection_b3/dataops_pipeline/.venv/lib/python3.11/site-packages/google/cloud/bigquery/client.py", line 831, in _call_api
    return call()
           ^^^^^^
  File "/home/arthurcornelio88/jedha/automatic_fraud_detection_b3/dataops_pipeline/.venv/lib/python3.11/site-packages/google/api_core/retry/retry_unary.py", line 294, in retry_wrapped_func
    return retry_target(
           ^^^^^^^^^^^^^
  File "/home/arthurcornelio88/jedha/automatic_fraud_detection_b3/dataops_pipeline/.venv/lib/python3.11/site-packages/google/api_core/retry/retry_unary.py", line 156, in retry_target
    next_sleep = _retry_error_helper(
                 ^^^^^^^^^^^^^^^^^^^^
  File "/home/arthurcornelio88/jedha/automatic_fraud_detection_b3/dataops_pipeline/.venv/lib/python3.11/site-packages/google/api_core/retry/retry_base.py", line 214, in _retry_error_helper
    raise final_exc from source_exc
  File "/home/arthurcornelio88/jedha/automatic_fraud_detection_b3/dataops_pipeline/.venv/lib/python3.11/site-packages/google/api_core/retry/retry_unary.py", line 147, in retry_target
    result = target()
             ^^^^^^^^
  File "/home/arthurcornelio88/jedha/automatic_fraud_detection_b3/dataops_pipeline/.venv/lib/python3.11/site-packages/google/cloud/_http/__init__.py", line 494, in api_request
    raise exceptions.from_http_response(response)
google.api_core.exceptions.BadRequest: 400 GET https://bigquery.googleapis.com/bigquery/v2/projects/your_project/datasets/raw_api_data/tables/daily_20250708?prettyPrint=false: Invalid resource name projects/your_project; Project id: your_project
[2025-07-08T20:38:24.301+0200] {taskinstance.py:1149} INFO - Marking task as UP_FOR_RETRY. dag_id=daily_fetch_transactions, task_id=fetch_transactions_to_bigquery, execution_date=20250708T183800, start_date=20250708T183803, end_date=20250708T183824
[2025-07-08T20:38:24.319+0200] {standard_task_runner.py:107} ERROR - Failed to execute job 12 for task fetch_transactions_to_bigquery (400 GET https://bigquery.googleapis.com/bigquery/v2/projects/your_project/datasets/raw_api_data/tables/daily_20250708?prettyPrint=false: Invalid resource name projects/your_project; Project id: your_project; 24075)
[2025-07-08T20:38:24.349+0200] {local_task_job_runner.py:234} INFO - Task exited with return code 1
[2025-07-08T20:38:24.370+0200] {taskinstance.py:3312} INFO - 0 downstream tasks scheduled from follow-on schedule check
