[2025-07-07T22:21:40.869+0200] {taskinstance.py:1979} INFO - Dependencies all met for dep_context=non-requeueable deps ti=<TaskInstance: daily_prediction.predict_on_daily_data manual__2025-07-07T20:21:38.233365+00:00 [queued]>
[2025-07-07T22:21:40.872+0200] {taskinstance.py:1979} INFO - Dependencies all met for dep_context=requeueable deps ti=<TaskInstance: daily_prediction.predict_on_daily_data manual__2025-07-07T20:21:38.233365+00:00 [queued]>
[2025-07-07T22:21:40.873+0200] {taskinstance.py:2193} INFO - Starting attempt 1 of 2
[2025-07-07T22:21:40.882+0200] {taskinstance.py:2217} INFO - Executing <Task(PythonOperator): predict_on_daily_data> on 2025-07-07 20:21:38.233365+00:00
[2025-07-07T22:21:40.887+0200] {standard_task_runner.py:60} INFO - Started process 90997 to run task
[2025-07-07T22:21:40.890+0200] {standard_task_runner.py:87} INFO - Running: ['airflow', 'tasks', 'run', 'daily_prediction', 'predict_on_daily_data', 'manual__2025-07-07T20:21:38.233365+00:00', '--job-id', '14', '--raw', '--subdir', 'DAGS_FOLDER/dag_daily_prediction.py', '--cfg-path', '/tmp/tmpfmg8tg75']
[2025-07-07T22:21:40.892+0200] {standard_task_runner.py:88} INFO - Job 14: Subtask predict_on_daily_data
[2025-07-07T22:21:40.925+0200] {task_command.py:423} INFO - Running <TaskInstance: daily_prediction.predict_on_daily_data manual__2025-07-07T20:21:38.233365+00:00 [running]> on host Datacraft-AC.localdomain
[2025-07-07T22:21:40.970+0200] {taskinstance.py:2513} INFO - Exporting env vars: AIRFLOW_CTX_DAG_OWNER='airflow' AIRFLOW_CTX_DAG_ID='daily_prediction' AIRFLOW_CTX_TASK_ID='predict_on_daily_data' AIRFLOW_CTX_EXECUTION_DATE='2025-07-07T20:21:38.233365+00:00' AIRFLOW_CTX_TRY_NUMBER='1' AIRFLOW_CTX_DAG_RUN_ID='manual__2025-07-07T20:21:38.233365+00:00'
[2025-07-07T22:21:42.341+0200] {taskinstance.py:2731} ERROR - Task failed with exception
Traceback (most recent call last):
  File "/home/arthurcornelio88/jedha/automatic_fraud_detection_b3/dataops_pipeline/.venv/lib/python3.11/site-packages/airflow/models/taskinstance.py", line 444, in _execute_task
    result = _execute_callable(context=context, **execute_callable_kwargs)
             ^^^^^^^^^^^^^^^^^^^^^^^^^^^^^^^^^^^^^^^^^^^^^^^^^^^^^^^^^^^^^
  File "/home/arthurcornelio88/jedha/automatic_fraud_detection_b3/dataops_pipeline/.venv/lib/python3.11/site-packages/airflow/models/taskinstance.py", line 414, in _execute_callable
    return execute_callable(context=context, **execute_callable_kwargs)
           ^^^^^^^^^^^^^^^^^^^^^^^^^^^^^^^^^^^^^^^^^^^^^^^^^^^^^^^^^^^^
  File "/home/arthurcornelio88/jedha/automatic_fraud_detection_b3/dataops_pipeline/.venv/lib/python3.11/site-packages/airflow/operators/python.py", line 200, in execute
    return_value = self.execute_callable()
                   ^^^^^^^^^^^^^^^^^^^^^^^
  File "/home/arthurcornelio88/jedha/automatic_fraud_detection_b3/dataops_pipeline/.venv/lib/python3.11/site-packages/airflow/operators/python.py", line 217, in execute_callable
    return self.python_callable(*self.op_args, **self.op_kwargs)
           ^^^^^^^^^^^^^^^^^^^^^^^^^^^^^^^^^^^^^^^^^^^^^^^^^^^^^
  File "/home/arthurcornelio88/jedha/automatic_fraud_detection_b3/dataops_pipeline/dags/dag_daily_prediction.py", line 32, in run_daily_prediction
    df.to_csv(input_path, index=False)
  File "/home/arthurcornelio88/jedha/automatic_fraud_detection_b3/dataops_pipeline/.venv/lib/python3.11/site-packages/pandas/core/generic.py", line 3902, in to_csv
    return DataFrameRenderer(formatter).to_csv(
           ^^^^^^^^^^^^^^^^^^^^^^^^^^^^^^^^^^^^
  File "/home/arthurcornelio88/jedha/automatic_fraud_detection_b3/dataops_pipeline/.venv/lib/python3.11/site-packages/pandas/io/formats/format.py", line 1152, in to_csv
    csv_formatter.save()
  File "/home/arthurcornelio88/jedha/automatic_fraud_detection_b3/dataops_pipeline/.venv/lib/python3.11/site-packages/pandas/io/formats/csvs.py", line 247, in save
    with get_handle(
         ^^^^^^^^^^^
  File "/home/arthurcornelio88/jedha/automatic_fraud_detection_b3/dataops_pipeline/.venv/lib/python3.11/site-packages/pandas/io/common.py", line 739, in get_handle
    check_parent_directory(str(handle))
  File "/home/arthurcornelio88/jedha/automatic_fraud_detection_b3/dataops_pipeline/.venv/lib/python3.11/site-packages/pandas/io/common.py", line 604, in check_parent_directory
    raise OSError(rf"Cannot save file into a non-existent directory: '{parent}'")
OSError: Cannot save file into a non-existent directory: '/app/data'
[2025-07-07T22:21:42.350+0200] {taskinstance.py:1149} INFO - Marking task as UP_FOR_RETRY. dag_id=daily_prediction, task_id=predict_on_daily_data, execution_date=20250707T202138, start_date=20250707T202140, end_date=20250707T202142
[2025-07-07T22:21:42.358+0200] {standard_task_runner.py:107} ERROR - Failed to execute job 14 for task predict_on_daily_data (Cannot save file into a non-existent directory: '/app/data'; 90997)
[2025-07-07T22:21:42.391+0200] {local_task_job_runner.py:234} INFO - Task exited with return code 1
[2025-07-07T22:21:42.399+0200] {taskinstance.py:3312} INFO - 0 downstream tasks scheduled from follow-on schedule check
