[2025-07-08T20:38:28.766+0200] {taskinstance.py:1979} INFO - Dependencies all met for dep_context=non-requeueable deps ti=<TaskInstance: daily_fetch_transactions.fetch_transactions_to_bigquery manual__2025-07-08T18:35:42.084553+00:00 [queued]>
[2025-07-08T20:38:28.774+0200] {taskinstance.py:1979} INFO - Dependencies all met for dep_context=requeueable deps ti=<TaskInstance: daily_fetch_transactions.fetch_transactions_to_bigquery manual__2025-07-08T18:35:42.084553+00:00 [queued]>
[2025-07-08T20:38:28.775+0200] {taskinstance.py:2193} INFO - Starting attempt 2 of 2
[2025-07-08T20:38:28.791+0200] {taskinstance.py:2217} INFO - Executing <Task(PythonOperator): fetch_transactions_to_bigquery> on 2025-07-08 18:35:42.084553+00:00
[2025-07-08T20:38:28.802+0200] {standard_task_runner.py:60} INFO - Started process 25115 to run task
[2025-07-08T20:38:28.806+0200] {standard_task_runner.py:87} INFO - Running: ['airflow', 'tasks', 'run', 'daily_fetch_transactions', 'fetch_transactions_to_bigquery', 'manual__2025-07-08T18:35:42.084553+00:00', '--job-id', '13', '--raw', '--subdir', 'DAGS_FOLDER/dag_daily_fetch_transactions.py', '--cfg-path', '/tmp/tmpl8fvpuix']
[2025-07-08T20:38:28.809+0200] {standard_task_runner.py:88} INFO - Job 13: Subtask fetch_transactions_to_bigquery
[2025-07-08T20:38:28.860+0200] {task_command.py:423} INFO - Running <TaskInstance: daily_fetch_transactions.fetch_transactions_to_bigquery manual__2025-07-08T18:35:42.084553+00:00 [running]> on host Datacraft-AC.localdomain
[2025-07-08T20:38:28.922+0200] {taskinstance.py:2513} INFO - Exporting env vars: AIRFLOW_CTX_DAG_OWNER='airflow' AIRFLOW_CTX_DAG_ID='daily_fetch_transactions' AIRFLOW_CTX_TASK_ID='fetch_transactions_to_bigquery' AIRFLOW_CTX_EXECUTION_DATE='2025-07-08T18:35:42.084553+00:00' AIRFLOW_CTX_TRY_NUMBER='2' AIRFLOW_CTX_DAG_RUN_ID='manual__2025-07-08T18:35:42.084553+00:00'
[2025-07-08T20:38:41.476+0200] {taskinstance.py:2731} ERROR - Task failed with exception
Traceback (most recent call last):
  File "/home/arthurcornelio88/jedha/automatic_fraud_detection_b3/dataops_pipeline/.venv/lib/python3.11/site-packages/airflow/models/taskinstance.py", line 444, in _execute_task
    result = _execute_callable(context=context, **execute_callable_kwargs)
             ^^^^^^^^^^^^^^^^^^^^^^^^^^^^^^^^^^^^^^^^^^^^^^^^^^^^^^^^^^^^^
  File "/home/arthurcornelio88/jedha/automatic_fraud_detection_b3/dataops_pipeline/.venv/lib/python3.11/site-packages/airflow/models/taskinstance.py", line 414, in _execute_callable
    return execute_callable(context=context, **execute_callable_kwargs)
           ^^^^^^^^^^^^^^^^^^^^^^^^^^^^^^^^^^^^^^^^^^^^^^^^^^^^^^^^^^^^
  File "/home/arthurcornelio88/jedha/automatic_fraud_detection_b3/dataops_pipeline/.venv/lib/python3.11/site-packages/airflow/operators/python.py", line 200, in execute
    return_value = self.execute_callable()
                   ^^^^^^^^^^^^^^^^^^^^^^^
  File "/home/arthurcornelio88/jedha/automatic_fraud_detection_b3/dataops_pipeline/.venv/lib/python3.11/site-packages/airflow/operators/python.py", line 217, in execute_callable
    return self.python_callable(*self.op_args, **self.op_kwargs)
           ^^^^^^^^^^^^^^^^^^^^^^^^^^^^^^^^^^^^^^^^^^^^^^^^^^^^^
  File "/home/arthurcornelio88/jedha/automatic_fraud_detection_b3/dataops_pipeline/dags/dag_daily_fetch_transactions.py", line 35, in fetch_transactions_to_bq
    df.to_gbq(destination_table=table_id, project_id=BQ_PROJECT, if_exists="replace", location=BQ_LOCATION)
  File "/home/arthurcornelio88/jedha/automatic_fraud_detection_b3/dataops_pipeline/.venv/lib/python3.11/site-packages/pandas/core/frame.py", line 2158, in to_gbq
    gbq.to_gbq(
  File "/home/arthurcornelio88/jedha/automatic_fraud_detection_b3/dataops_pipeline/.venv/lib/python3.11/site-packages/pandas/io/gbq.py", line 223, in to_gbq
    pandas_gbq.to_gbq(
  File "/home/arthurcornelio88/jedha/automatic_fraud_detection_b3/dataops_pipeline/.venv/lib/python3.11/site-packages/pandas_gbq/gbq.py", line 604, in to_gbq
    table = bqclient.get_table(destination_table_ref)
            ^^^^^^^^^^^^^^^^^^^^^^^^^^^^^^^^^^^^^^^^^
  File "/home/arthurcornelio88/jedha/automatic_fraud_detection_b3/dataops_pipeline/.venv/lib/python3.11/site-packages/google/cloud/bigquery/client.py", line 1158, in get_table
    api_response = self._call_api(
                   ^^^^^^^^^^^^^^^
  File "/home/arthurcornelio88/jedha/automatic_fraud_detection_b3/dataops_pipeline/.venv/lib/python3.11/site-packages/google/cloud/bigquery/client.py", line 831, in _call_api
    return call()
           ^^^^^^
  File "/home/arthurcornelio88/jedha/automatic_fraud_detection_b3/dataops_pipeline/.venv/lib/python3.11/site-packages/google/api_core/retry/retry_unary.py", line 294, in retry_wrapped_func
    return retry_target(
           ^^^^^^^^^^^^^
  File "/home/arthurcornelio88/jedha/automatic_fraud_detection_b3/dataops_pipeline/.venv/lib/python3.11/site-packages/google/api_core/retry/retry_unary.py", line 156, in retry_target
    next_sleep = _retry_error_helper(
                 ^^^^^^^^^^^^^^^^^^^^
  File "/home/arthurcornelio88/jedha/automatic_fraud_detection_b3/dataops_pipeline/.venv/lib/python3.11/site-packages/google/api_core/retry/retry_base.py", line 214, in _retry_error_helper
    raise final_exc from source_exc
  File "/home/arthurcornelio88/jedha/automatic_fraud_detection_b3/dataops_pipeline/.venv/lib/python3.11/site-packages/google/api_core/retry/retry_unary.py", line 147, in retry_target
    result = target()
             ^^^^^^^^
  File "/home/arthurcornelio88/jedha/automatic_fraud_detection_b3/dataops_pipeline/.venv/lib/python3.11/site-packages/google/cloud/_http/__init__.py", line 494, in api_request
    raise exceptions.from_http_response(response)
google.api_core.exceptions.BadRequest: 400 GET https://bigquery.googleapis.com/bigquery/v2/projects/your_project/datasets/raw_api_data/tables/daily_20250708?prettyPrint=false: Invalid resource name projects/your_project; Project id: your_project
[2025-07-08T20:38:41.488+0200] {taskinstance.py:1149} INFO - Marking task as FAILED. dag_id=daily_fetch_transactions, task_id=fetch_transactions_to_bigquery, execution_date=20250708T183542, start_date=20250708T183828, end_date=20250708T183841
[2025-07-08T20:38:41.502+0200] {standard_task_runner.py:107} ERROR - Failed to execute job 13 for task fetch_transactions_to_bigquery (400 GET https://bigquery.googleapis.com/bigquery/v2/projects/your_project/datasets/raw_api_data/tables/daily_20250708?prettyPrint=false: Invalid resource name projects/your_project; Project id: your_project; 25115)
[2025-07-08T20:38:41.526+0200] {local_task_job_runner.py:234} INFO - Task exited with return code 1
[2025-07-08T20:38:41.538+0200] {taskinstance.py:3312} INFO - 0 downstream tasks scheduled from follow-on schedule check
