[2025-07-08T20:52:59.857+0200] {taskinstance.py:1979} INFO - Dependencies all met for dep_context=non-requeueable deps ti=<TaskInstance: daily_prediction.predict_on_daily_data __airflow_temporary_run_2025-07-08T18:52:57.660902+00:00__ [queued]>
[2025-07-08T20:52:59.859+0200] {taskinstance.py:1979} INFO - Dependencies all met for dep_context=requeueable deps ti=<TaskInstance: daily_prediction.predict_on_daily_data __airflow_temporary_run_2025-07-08T18:52:57.660902+00:00__ [queued]>
[2025-07-08T20:52:59.859+0200] {taskinstance.py:2193} INFO - Starting attempt 1 of 2
[2025-07-08T20:52:59.869+0200] {taskinstance.py:2217} INFO - Executing <Task(PythonOperator): predict_on_daily_data> on 2025-07-08 00:00:00+00:00
[2025-07-08T20:52:59.874+0200] {standard_task_runner.py:60} INFO - Started process 27624 to run task
[2025-07-08T20:52:59.879+0200] {standard_task_runner.py:87} INFO - Running: ['airflow', 'tasks', 'run', 'daily_prediction', 'predict_on_daily_data', '__airflow_temporary_run_2025-07-08T18:52:57.660902+00:00__', '--job-id', '17', '--raw', '--subdir', 'DAGS_FOLDER/dag_daily_prediction.py', '--cfg-path', '/tmp/tmphrun0b7e']
[2025-07-08T20:52:59.881+0200] {standard_task_runner.py:88} INFO - Job 17: Subtask predict_on_daily_data
[2025-07-08T20:52:59.921+0200] {task_command.py:423} INFO - Running <TaskInstance: daily_prediction.predict_on_daily_data __airflow_temporary_run_2025-07-08T18:52:57.660902+00:00__ [running]> on host Datacraft-AC.localdomain
[2025-07-08T20:52:59.967+0200] {taskinstance.py:2513} INFO - Exporting env vars: AIRFLOW_CTX_DAG_OWNER='airflow' AIRFLOW_CTX_DAG_ID='daily_prediction' AIRFLOW_CTX_TASK_ID='predict_on_daily_data' AIRFLOW_CTX_EXECUTION_DATE='2025-07-08T00:00:00+00:00' AIRFLOW_CTX_TRY_NUMBER='1' AIRFLOW_CTX_DAG_RUN_ID='__airflow_temporary_run_2025-07-08T18:52:57.660902+00:00__'
[2025-07-08T20:52:59.969+0200] {logging_mixin.py:188} INFO - ðŸ“¥ Reading from BigQuery table: your_project.raw_api_data.daily_20250708
[2025-07-08T20:53:11.937+0200] {taskinstance.py:2731} ERROR - Task failed with exception
Traceback (most recent call last):
  File "/home/arthurcornelio88/jedha/automatic_fraud_detection_b3/dataops_pipeline/.venv/lib/python3.11/site-packages/airflow/models/taskinstance.py", line 444, in _execute_task
    result = _execute_callable(context=context, **execute_callable_kwargs)
             ^^^^^^^^^^^^^^^^^^^^^^^^^^^^^^^^^^^^^^^^^^^^^^^^^^^^^^^^^^^^^
  File "/home/arthurcornelio88/jedha/automatic_fraud_detection_b3/dataops_pipeline/.venv/lib/python3.11/site-packages/airflow/models/taskinstance.py", line 414, in _execute_callable
    return execute_callable(context=context, **execute_callable_kwargs)
           ^^^^^^^^^^^^^^^^^^^^^^^^^^^^^^^^^^^^^^^^^^^^^^^^^^^^^^^^^^^^
  File "/home/arthurcornelio88/jedha/automatic_fraud_detection_b3/dataops_pipeline/.venv/lib/python3.11/site-packages/airflow/operators/python.py", line 200, in execute
    return_value = self.execute_callable()
                   ^^^^^^^^^^^^^^^^^^^^^^^
  File "/home/arthurcornelio88/jedha/automatic_fraud_detection_b3/dataops_pipeline/.venv/lib/python3.11/site-packages/airflow/operators/python.py", line 217, in execute_callable
    return self.python_callable(*self.op_args, **self.op_kwargs)
           ^^^^^^^^^^^^^^^^^^^^^^^^^^^^^^^^^^^^^^^^^^^^^^^^^^^^^
  File "/home/arthurcornelio88/jedha/automatic_fraud_detection_b3/dataops_pipeline/dags/dag_daily_prediction.py", line 31, in run_daily_prediction
    bq = bigquery.Client()
         ^^^^^^^^^^^^^^^^^
  File "/home/arthurcornelio88/jedha/automatic_fraud_detection_b3/dataops_pipeline/.venv/lib/python3.11/site-packages/google/cloud/bigquery/client.py", line 241, in __init__
    super(Client, self).__init__(
  File "/home/arthurcornelio88/jedha/automatic_fraud_detection_b3/dataops_pipeline/.venv/lib/python3.11/site-packages/google/cloud/client/__init__.py", line 338, in __init__
    _ClientProjectMixin.__init__(self, project=project, credentials=credentials)
  File "/home/arthurcornelio88/jedha/automatic_fraud_detection_b3/dataops_pipeline/.venv/lib/python3.11/site-packages/google/cloud/client/__init__.py", line 286, in __init__
    project = self._determine_default(project)
              ^^^^^^^^^^^^^^^^^^^^^^^^^^^^^^^^
  File "/home/arthurcornelio88/jedha/automatic_fraud_detection_b3/dataops_pipeline/.venv/lib/python3.11/site-packages/google/cloud/client/__init__.py", line 305, in _determine_default
    return _determine_default_project(project)
           ^^^^^^^^^^^^^^^^^^^^^^^^^^^^^^^^^^^
  File "/home/arthurcornelio88/jedha/automatic_fraud_detection_b3/dataops_pipeline/.venv/lib/python3.11/site-packages/google/cloud/_helpers/__init__.py", line 152, in _determine_default_project
    _, project = google.auth.default()
                 ^^^^^^^^^^^^^^^^^^^^^
  File "/home/arthurcornelio88/jedha/automatic_fraud_detection_b3/dataops_pipeline/.venv/lib/python3.11/site-packages/google/auth/_default.py", line 685, in default
    raise exceptions.DefaultCredentialsError(_CLOUD_SDK_MISSING_CREDENTIALS)
google.auth.exceptions.DefaultCredentialsError: Your default credentials were not found. To set up Application Default Credentials, see https://cloud.google.com/docs/authentication/external/set-up-adc for more information.
[2025-07-08T20:53:11.943+0200] {taskinstance.py:1149} INFO - Marking task as FAILED. dag_id=daily_prediction, task_id=predict_on_daily_data, execution_date=20250708T000000, start_date=20250708T185259, end_date=20250708T185311
[2025-07-08T20:53:11.950+0200] {standard_task_runner.py:107} ERROR - Failed to execute job 17 for task predict_on_daily_data ((sqlite3.IntegrityError) FOREIGN KEY constraint failed
[SQL: INSERT INTO task_fail (task_id, dag_id, run_id, map_index, start_date, end_date, duration) VALUES (?, ?, ?, ?, ?, ?, ?)]
[parameters: ('predict_on_daily_data', 'daily_prediction', '__airflow_temporary_run_2025-07-08T18:52:57.660902+00:00__', -1, '2025-07-08 18:52:59.857195', '2025-07-08 18:53:11.943356', 12)]
(Background on this error at: https://sqlalche.me/e/14/gkpj); 27624)
[2025-07-08T20:53:11.988+0200] {local_task_job_runner.py:234} INFO - Task exited with return code 1
