[2025-07-08T23:12:15.193+0200] {taskinstance.py:1979} INFO - Dependencies all met for dep_context=non-requeueable deps ti=<TaskInstance: daily_fetch_transactions.fetch_transactions_to_bigquery __airflow_temporary_run_2025-07-08T21:12:12.569937+00:00__ [queued]>
[2025-07-08T23:12:15.199+0200] {taskinstance.py:1979} INFO - Dependencies all met for dep_context=requeueable deps ti=<TaskInstance: daily_fetch_transactions.fetch_transactions_to_bigquery __airflow_temporary_run_2025-07-08T21:12:12.569937+00:00__ [queued]>
[2025-07-08T23:12:15.199+0200] {taskinstance.py:2193} INFO - Starting attempt 1 of 2
[2025-07-08T23:12:15.212+0200] {taskinstance.py:2217} INFO - Executing <Task(PythonOperator): fetch_transactions_to_bigquery> on 2025-07-08 00:00:00+00:00
[2025-07-08T23:12:15.218+0200] {standard_task_runner.py:60} INFO - Started process 59107 to run task
[2025-07-08T23:12:15.225+0200] {standard_task_runner.py:87} INFO - Running: ['airflow', 'tasks', 'run', 'daily_fetch_transactions', 'fetch_transactions_to_bigquery', '__airflow_temporary_run_2025-07-08T21:12:12.569937+00:00__', '--job-id', '18', '--raw', '--subdir', 'DAGS_FOLDER/dag_daily_fetch_transactions.py', '--cfg-path', '/tmp/tmpsy86sgps']
[2025-07-08T23:12:15.229+0200] {standard_task_runner.py:88} INFO - Job 18: Subtask fetch_transactions_to_bigquery
[2025-07-08T23:12:15.288+0200] {task_command.py:423} INFO - Running <TaskInstance: daily_fetch_transactions.fetch_transactions_to_bigquery __airflow_temporary_run_2025-07-08T21:12:12.569937+00:00__ [running]> on host Datacraft-AC.localdomain
[2025-07-08T23:12:15.348+0200] {taskinstance.py:2513} INFO - Exporting env vars: AIRFLOW_CTX_DAG_OWNER='airflow' AIRFLOW_CTX_DAG_ID='daily_fetch_transactions' AIRFLOW_CTX_TASK_ID='fetch_transactions_to_bigquery' AIRFLOW_CTX_EXECUTION_DATE='2025-07-08T00:00:00+00:00' AIRFLOW_CTX_TRY_NUMBER='1' AIRFLOW_CTX_DAG_RUN_ID='__airflow_temporary_run_2025-07-08T21:12:12.569937+00:00__'
[2025-07-08T23:12:15.349+0200] {logging_mixin.py:188} INFO - üåê Fetching from: http://localhost:8001/transactions?n=500&variability=medium
[2025-07-08T23:12:25.282+0200] {local_task_job_runner.py:302} WARNING - State of this instance has been externally set to None. Terminating instance.
[2025-07-08T23:12:25.289+0200] {process_utils.py:131} INFO - Sending 15 to group 59107. PIDs of all processes in the group: [59107]
[2025-07-08T23:12:25.289+0200] {process_utils.py:86} INFO - Sending the signal 15 to group 59107
[2025-07-08T23:12:25.289+0200] {taskinstance.py:2483} ERROR - Received SIGTERM. Terminating subprocesses.
[2025-07-08T23:12:25.295+0200] {taskinstance.py:2731} ERROR - Task failed with exception
Traceback (most recent call last):
  File "/home/arthurcornelio88/jedha/automatic_fraud_detection_b3/dataops_pipeline/.venv/lib/python3.11/site-packages/airflow/models/taskinstance.py", line 444, in _execute_task
    result = _execute_callable(context=context, **execute_callable_kwargs)
             ^^^^^^^^^^^^^^^^^^^^^^^^^^^^^^^^^^^^^^^^^^^^^^^^^^^^^^^^^^^^^
  File "/home/arthurcornelio88/jedha/automatic_fraud_detection_b3/dataops_pipeline/.venv/lib/python3.11/site-packages/airflow/models/taskinstance.py", line 414, in _execute_callable
    return execute_callable(context=context, **execute_callable_kwargs)
           ^^^^^^^^^^^^^^^^^^^^^^^^^^^^^^^^^^^^^^^^^^^^^^^^^^^^^^^^^^^^
  File "/home/arthurcornelio88/jedha/automatic_fraud_detection_b3/dataops_pipeline/.venv/lib/python3.11/site-packages/airflow/operators/python.py", line 200, in execute
    return_value = self.execute_callable()
                   ^^^^^^^^^^^^^^^^^^^^^^^
  File "/home/arthurcornelio88/jedha/automatic_fraud_detection_b3/dataops_pipeline/.venv/lib/python3.11/site-packages/airflow/operators/python.py", line 217, in execute_callable
    return self.python_callable(*self.op_args, **self.op_kwargs)
           ^^^^^^^^^^^^^^^^^^^^^^^^^^^^^^^^^^^^^^^^^^^^^^^^^^^^^
  File "/home/arthurcornelio88/jedha/automatic_fraud_detection_b3/dataops_pipeline/dags/dag_daily_fetch_transactions.py", line 40, in fetch_transactions_to_bq
    df.to_gbq(destination_table=table_id, project_id=BQ_PROJECT, if_exists="replace", location=BQ_LOCATION)
  File "/home/arthurcornelio88/jedha/automatic_fraud_detection_b3/dataops_pipeline/.venv/lib/python3.11/site-packages/pandas/core/frame.py", line 2158, in to_gbq
    gbq.to_gbq(
  File "/home/arthurcornelio88/jedha/automatic_fraud_detection_b3/dataops_pipeline/.venv/lib/python3.11/site-packages/pandas/io/gbq.py", line 223, in to_gbq
    pandas_gbq.to_gbq(
  File "/home/arthurcornelio88/jedha/automatic_fraud_detection_b3/dataops_pipeline/.venv/lib/python3.11/site-packages/pandas_gbq/gbq.py", line 568, in to_gbq
    connector = GbqConnector(
                ^^^^^^^^^^^^^
  File "/home/arthurcornelio88/jedha/automatic_fraud_detection_b3/dataops_pipeline/.venv/lib/python3.11/site-packages/pandas_gbq/gbq_connector.py", line 100, in __init__
    self.credentials, default_project = auth.get_credentials(
                                        ^^^^^^^^^^^^^^^^^^^^^
  File "/home/arthurcornelio88/jedha/automatic_fraud_detection_b3/dataops_pipeline/.venv/lib/python3.11/site-packages/pandas_gbq/auth.py", line 37, in get_credentials
    credentials, default_project_id = pydata_google_auth.default(
                                      ^^^^^^^^^^^^^^^^^^^^^^^^^^^
  File "/home/arthurcornelio88/jedha/automatic_fraud_detection_b3/dataops_pipeline/.venv/lib/python3.11/site-packages/pydata_google_auth/auth.py", line 146, in default
    credentials, default_project = get_application_default_credentials(scopes)
                                   ^^^^^^^^^^^^^^^^^^^^^^^^^^^^^^^^^^^^^^^^^^^
  File "/home/arthurcornelio88/jedha/automatic_fraud_detection_b3/dataops_pipeline/.venv/lib/python3.11/site-packages/pydata_google_auth/auth.py", line 231, in get_application_default_credentials
    credentials, project = google.auth.default(scopes=scopes)
                           ^^^^^^^^^^^^^^^^^^^^^^^^^^^^^^^^^^
  File "/home/arthurcornelio88/jedha/automatic_fraud_detection_b3/dataops_pipeline/.venv/lib/python3.11/site-packages/google/auth/_default.py", line 651, in default
    credentials, project_id = checker()
                              ^^^^^^^^^
  File "/home/arthurcornelio88/jedha/automatic_fraud_detection_b3/dataops_pipeline/.venv/lib/python3.11/site-packages/google/auth/_default.py", line 647, in <lambda>
    lambda: _get_gce_credentials(request, quota_project_id=quota_project_id),
            ^^^^^^^^^^^^^^^^^^^^^^^^^^^^^^^^^^^^^^^^^^^^^^^^^^^^^^^^^^^^^^^^
  File "/home/arthurcornelio88/jedha/automatic_fraud_detection_b3/dataops_pipeline/.venv/lib/python3.11/site-packages/google/auth/_default.py", line 350, in _get_gce_credentials
    if _metadata.is_on_gce(request=request):
       ^^^^^^^^^^^^^^^^^^^^^^^^^^^^^^^^^^^^
  File "/home/arthurcornelio88/jedha/automatic_fraud_detection_b3/dataops_pipeline/.venv/lib/python3.11/site-packages/google/auth/compute_engine/_metadata.py", line 78, in is_on_gce
    if ping(request):
       ^^^^^^^^^^^^^
  File "/home/arthurcornelio88/jedha/automatic_fraud_detection_b3/dataops_pipeline/.venv/lib/python3.11/site-packages/google/auth/compute_engine/_metadata.py", line 131, in ping
    response = request(
               ^^^^^^^^
  File "/home/arthurcornelio88/jedha/automatic_fraud_detection_b3/dataops_pipeline/.venv/lib/python3.11/site-packages/google/auth/transport/_http_client.py", line 105, in __call__
    connection.request(method, path, body=body, headers=headers, **kwargs)
  File "/home/arthurcornelio88/.local/share/uv/python/cpython-3.11.13-linux-x86_64-gnu/lib/python3.11/http/client.py", line 1303, in request
    self._send_request(method, url, body, headers, encode_chunked)
  File "/home/arthurcornelio88/.local/share/uv/python/cpython-3.11.13-linux-x86_64-gnu/lib/python3.11/http/client.py", line 1349, in _send_request
    self.endheaders(body, encode_chunked=encode_chunked)
  File "/home/arthurcornelio88/.local/share/uv/python/cpython-3.11.13-linux-x86_64-gnu/lib/python3.11/http/client.py", line 1298, in endheaders
    self._send_output(message_body, encode_chunked=encode_chunked)
  File "/home/arthurcornelio88/.local/share/uv/python/cpython-3.11.13-linux-x86_64-gnu/lib/python3.11/http/client.py", line 1058, in _send_output
    self.send(msg)
  File "/home/arthurcornelio88/.local/share/uv/python/cpython-3.11.13-linux-x86_64-gnu/lib/python3.11/http/client.py", line 996, in send
    self.connect()
  File "/home/arthurcornelio88/.local/share/uv/python/cpython-3.11.13-linux-x86_64-gnu/lib/python3.11/http/client.py", line 962, in connect
    self.sock = self._create_connection(
                ^^^^^^^^^^^^^^^^^^^^^^^^
  File "/home/arthurcornelio88/.local/share/uv/python/cpython-3.11.13-linux-x86_64-gnu/lib/python3.11/socket.py", line 848, in create_connection
    sock.connect(sa)
  File "/home/arthurcornelio88/jedha/automatic_fraud_detection_b3/dataops_pipeline/.venv/lib/python3.11/site-packages/airflow/models/taskinstance.py", line 2485, in signal_handler
    raise AirflowException("Task received SIGTERM signal")
airflow.exceptions.AirflowException: Task received SIGTERM signal
[2025-07-08T23:12:25.310+0200] {taskinstance.py:1149} INFO - Marking task as FAILED. dag_id=daily_fetch_transactions, task_id=fetch_transactions_to_bigquery, execution_date=20250708T000000, start_date=20250708T211215, end_date=20250708T211225
[2025-07-08T23:12:25.319+0200] {standard_task_runner.py:107} ERROR - Failed to execute job 18 for task fetch_transactions_to_bigquery ((sqlite3.IntegrityError) FOREIGN KEY constraint failed
[SQL: UPDATE dag_run SET dag_id=?, queued_at=?, start_date=?, state=?, run_id=?, last_scheduling_decision=?, dag_hash=?, updated_at=? WHERE dag_run.id = ?]
[parameters: ('daily_fetch_transactions', '2025-07-08 21:12:12.571073', '2025-07-08 21:12:12.671278', 'running', '__airflow_temporary_run_2025-07-08T21:12:12.569937+00:00__', '2025-07-08 21:12:12.793910', '30ad9749eb9a4e3ac97915a26655c95c', '2025-07-08 21:12:12.819748', 8)]
(Background on this error at: https://sqlalche.me/e/14/gkpj); 59107)
[2025-07-08T23:12:25.342+0200] {process_utils.py:79} INFO - Process psutil.Process(pid=59107, status='terminated', exitcode=1, started='23:12:14') (59107) terminated with exit code 1
