[2025-07-07T22:32:17.946+0200] {taskinstance.py:1979} INFO - Dependencies all met for dep_context=non-requeueable deps ti=<TaskInstance: daily_prediction.predict_on_daily_data manual__2025-07-07T20:32:15.919316+00:00 [queued]>
[2025-07-07T22:32:17.949+0200] {taskinstance.py:1979} INFO - Dependencies all met for dep_context=requeueable deps ti=<TaskInstance: daily_prediction.predict_on_daily_data manual__2025-07-07T20:32:15.919316+00:00 [queued]>
[2025-07-07T22:32:17.949+0200] {taskinstance.py:2193} INFO - Starting attempt 1 of 2
[2025-07-07T22:32:17.958+0200] {taskinstance.py:2217} INFO - Executing <Task(PythonOperator): predict_on_daily_data> on 2025-07-07 20:32:15.919316+00:00
[2025-07-07T22:32:17.964+0200] {standard_task_runner.py:60} INFO - Started process 96995 to run task
[2025-07-07T22:32:17.968+0200] {standard_task_runner.py:87} INFO - Running: ['airflow', 'tasks', 'run', 'daily_prediction', 'predict_on_daily_data', 'manual__2025-07-07T20:32:15.919316+00:00', '--job-id', '18', '--raw', '--subdir', 'DAGS_FOLDER/dag_daily_prediction.py', '--cfg-path', '/tmp/tmpcoc8e5dy']
[2025-07-07T22:32:17.970+0200] {standard_task_runner.py:88} INFO - Job 18: Subtask predict_on_daily_data
[2025-07-07T22:32:18.005+0200] {task_command.py:423} INFO - Running <TaskInstance: daily_prediction.predict_on_daily_data manual__2025-07-07T20:32:15.919316+00:00 [running]> on host Datacraft-AC.localdomain
[2025-07-07T22:32:18.048+0200] {taskinstance.py:2513} INFO - Exporting env vars: AIRFLOW_CTX_DAG_OWNER='airflow' AIRFLOW_CTX_DAG_ID='daily_prediction' AIRFLOW_CTX_TASK_ID='predict_on_daily_data' AIRFLOW_CTX_EXECUTION_DATE='2025-07-07T20:32:15.919316+00:00' AIRFLOW_CTX_TRY_NUMBER='1' AIRFLOW_CTX_DAG_RUN_ID='manual__2025-07-07T20:32:15.919316+00:00'
[2025-07-07T22:32:20.218+0200] {taskinstance.py:2731} ERROR - Task failed with exception
Traceback (most recent call last):
  File "/home/arthurcornelio88/jedha/automatic_fraud_detection_b3/dataops_pipeline/.venv/lib/python3.11/site-packages/airflow/models/taskinstance.py", line 444, in _execute_task
    result = _execute_callable(context=context, **execute_callable_kwargs)
             ^^^^^^^^^^^^^^^^^^^^^^^^^^^^^^^^^^^^^^^^^^^^^^^^^^^^^^^^^^^^^
  File "/home/arthurcornelio88/jedha/automatic_fraud_detection_b3/dataops_pipeline/.venv/lib/python3.11/site-packages/airflow/models/taskinstance.py", line 414, in _execute_callable
    return execute_callable(context=context, **execute_callable_kwargs)
           ^^^^^^^^^^^^^^^^^^^^^^^^^^^^^^^^^^^^^^^^^^^^^^^^^^^^^^^^^^^^
  File "/home/arthurcornelio88/jedha/automatic_fraud_detection_b3/dataops_pipeline/.venv/lib/python3.11/site-packages/airflow/operators/python.py", line 200, in execute
    return_value = self.execute_callable()
                   ^^^^^^^^^^^^^^^^^^^^^^^
  File "/home/arthurcornelio88/jedha/automatic_fraud_detection_b3/dataops_pipeline/.venv/lib/python3.11/site-packages/airflow/operators/python.py", line 217, in execute_callable
    return self.python_callable(*self.op_args, **self.op_kwargs)
           ^^^^^^^^^^^^^^^^^^^^^^^^^^^^^^^^^^^^^^^^^^^^^^^^^^^^^
  File "/home/arthurcornelio88/jedha/automatic_fraud_detection_b3/dataops_pipeline/dags/dag_daily_prediction.py", line 44, in run_daily_prediction
    raise Exception(f"❌ Predict failed: {res.status_code} - {res.text}")
Exception: ❌ Predict failed: 400 - {"detail":"File not found: data/predict/input_20250707.csv"}
[2025-07-07T22:32:20.222+0200] {taskinstance.py:1149} INFO - Marking task as UP_FOR_RETRY. dag_id=daily_prediction, task_id=predict_on_daily_data, execution_date=20250707T203215, start_date=20250707T203217, end_date=20250707T203220
[2025-07-07T22:32:20.232+0200] {standard_task_runner.py:107} ERROR - Failed to execute job 18 for task predict_on_daily_data (❌ Predict failed: 400 - {"detail":"File not found: data/predict/input_20250707.csv"}; 96995)
[2025-07-07T22:32:20.270+0200] {local_task_job_runner.py:234} INFO - Task exited with return code 1
[2025-07-07T22:32:20.278+0200] {taskinstance.py:3312} INFO - 0 downstream tasks scheduled from follow-on schedule check
